Workbook

Sheet Start here
A1: Game Night
A2: Poker buy-ins and the FIFA tournament, shared by everyone with the link.
A4: 1. Players: add your name, pick your group, usual team, and whether you play poker and FIFA.
A5: 2. Buy-ins: add one row each time someone buys in. Leave Amount blank for a standard $20 buy-in.
A6: 3. Matches: when a FIFA game starts, add a row with both players and teams and set Status to Live.
A7: Update the goals as you play. Set Status to Final when it ends. For a knockout draw, pick who won on penalties.
A8: 4. Cash-out: at the end of the night, type how many chips of each colour each player has.
A9: 5. Leaderboard: live matches, group tables, the overall FIFA table and poker results update by themselves.
A11: Yellow cells are the ones to fill in. Everything else is calculated.
A12: Group names, the buy-in amount and chip values are on the Settings tab.
A13: Only Final matches count. Friendlies never count. 3 points for a win, 1 for a draw; ties split by goal difference, then goals scored.

Sheet Leaderboard
A1: Leaderboard
M2: sort key | N2: row
A3: Live now
A4: =IF($M4="","No matches live right now.",INDEX(Matches!$C:$C,$M4)&IF(INDEX(Matches!$D:$D,$M4)="",""," ("&INDEX(Matches!$D:$D,$M4)&")")&" "&N(INDEX(Matches!$E:$E,$M4))&" - "&N(INDEX(Matches!$F:$F,$M4))&" "&INDEX(Matches!$H:$H,$M4)&IF(INDEX(Matches!$G:$G,$M4)="",""," ("&INDEX(Matches!$G:$G,$M4)&")")&" ["&INDEX(Matches!$A:$A,$M4)&"]") | M4: =IFERROR(SMALL(Matches!$N:$N,1),"")
A5: =IF($M5="","",INDEX(Matches!$C:$C,$M5)&IF(INDEX(Matches!$D:$D,$M5)="",""," ("&INDEX(Matches!$D:$D,$M5)&")")&" "&N(INDEX(Matches!$E:$E,$M5))&" - "&N(INDEX(Matches!$F:$F,$M5))&" "&INDEX(Matches!$H:$H,$M5)&IF(INDEX(Matches!$G:$G,$M5)="",""," ("&INDEX(Matches!$G:$G,$M5)&")")&" ["&INDEX(Matches!$A:$A,$M5)&"]") | M5: =IFERROR(SMALL(Matches!$N:$N,2),"")
A6: =IF($M6="","",INDEX(Matches!$C:$C,$M6)&IF(INDEX(Matches!$D:$D,$M6)="",""," ("&INDEX(Matches!$D:$D,$M6)&")")&" "&N(INDEX(Matches!$E:$E,$M6))&" - "&N(INDEX(Matches!$F:$F,$M6))&" "&INDEX(Matches!$H:$H,$M6)&IF(INDEX(Matches!$G:$G,$M6)="",""," ("&INDEX(Matches!$G:$G,$M6)&")")&" ["&INDEX(Matches!$A:$A,$M6)&"]") | M6: =IFERROR(SMALL(Matches!$N:$N,3),"")
A7: =IF($M7="","",INDEX(Matches!$C:$C,$M7)&IF(INDEX(Matches!$D:$D,$M7)="",""," ("&INDEX(Matches!$D:$D,$M7)&")")&" "&N(INDEX(Matches!$E:$E,$M7))&" - "&N(INDEX(Matches!$F:$F,$M7))&" "&INDEX(Matches!$H:$H,$M7)&IF(INDEX(Matches!$G:$G,$M7)="",""," ("&INDEX(Matches!$G:$G,$M7)&")")&" ["&INDEX(Matches!$A:$A,$M7)&"]") | M7: =IFERROR(SMALL(Matches!$N:$N,4),"")
A9: =IF(Settings!$A$15="","Group 1 (add the name on the Settings tab)",Settings!$A$15)
A10: Rank | B10: Player | C10: Group | D10: P | E10: W | F10: D | G10: L | H10: GF | I10: GA | J10: GD | K10: Pts
A11: =IF($N11="","",1) | B11: =IF($N11="","",INDEX(Stats!$A$2:$A$26,$N11)) | C11: =IF($N11="","",INDEX(Stats!$B$2:$B$26,$N11)) | D11: =IF($N11="","",INDEX(Stats!$M$2:$M$26,$N11)) | E11: =IF($N11="","",INDEX(Stats!$N$2:$N$26,$N11)) | F11: =IF($N11="","",INDEX(Stats!$O$2:$O$26,$N11)) | G11: =IF($N11="","",INDEX(Stats!$P$2:$P$26,$N11)) | H11: =IF($N11="","",INDEX(Stats!$Q$2:$Q$26,$N11)) | I11: =IF($N11="","",INDEX(Stats!$R$2:$R$26,$N11)) | J11: =IF($N11="","",INDEX(Stats!$S$2:$S$26,$N11)) | K11: =IF($N11="","",INDEX(Stats!$T$2:$T$26,$N11)) | M11: =IFERROR(LARGE(Stats!$V$2:$V$26,COUNTIF(Stats!$V$2:$V$26,">="&2*1000000000)+1),-1) | N11: =IF($M11>=1*1000000000,MATCH($M11,Stats!$V$2:$V$26,0),"")
A12: =IF($N12="","",2) | B12: =IF($N12="","",INDEX(Stats!$A$2:$A$26,$N12)) | C12: =IF($N12="","",INDEX(Stats!$B$2:$B$26,$N12)) | D12: =IF($N12="","",INDEX(Stats!$M$2:$M$26,$N12)) | E12: =IF($N12="","",INDEX(Stats!$N$2:$N$26,$N12)) | F12: =IF($N12="","",INDEX(Stats!$O$2:$O$26,$N12)) | G12: =IF($N12="","",INDEX(Stats!$P$2:$P$26,$N12)) | H12: =IF($N12="","",INDEX(Stats!$Q$2:$Q$26,$N12)) | I12: =IF($N12="","",INDEX(Stats!$R$2:$R$26,$N12)) | J12: =IF($N12="","",INDEX(Stats!$S$2:$S$26,$N12)) | K12: =IF($N12="","",INDEX(Stats!$T$2:$T$26,$N12)) | M12: =IFERROR(LARGE(Stats!$V$2:$V$26,COUNTIF(Stats!$V$2:$V$26,">="&2*1000000000)+2),-1) | N12: =IF($M12>=1*1000000000,MATCH($M12,Stats!$V$2:$V$26,0),"")
A13: =IF($N13="","",3) | B13: =IF($N13="","",INDEX(Stats!$A$2:$A$26,$N13)) | C13: =IF($N13="","",INDEX(Stats!$B$2:$B$26,$N13)) | D13: =IF($N13="","",INDEX(Stats!$M$2:$M$26,$N13)) | E13: =IF($N13="","",INDEX(Stats!$N$2:$N$26,$N13)) | F13: =IF($N13="","",INDEX(Stats!$O$2:$O$26,$N13)) | G13: =IF($N13="","",INDEX(Stats!$P$2:$P$26,$N13)) | H13: =IF($N13="","",INDEX(Stats!$Q$2:$Q$26,$N13)) | I13: =IF($N13="","",INDEX(Stats!$R$2:$R$26,$N13)) | J13: =IF($N13="","",INDEX(Stats!$S$2:$S$26,$N13)) | K13: =IF($N13="","",INDEX(Stats!$T$2:$T$26,$N13)) | M13: =IFERROR(LARGE(Stats!$V$2:$V$26,COUNTIF(Stats!$V$2:$V$26,">="&2*1000000000)+3),-1) | N13: =IF($M13>=1*1000000000,MATCH($M13,Stats!$V$2:$V$26,0),"")
A14: =IF($N14="","",4) | B14: =IF($N14="","",INDEX(Stats!$A$2:$A$26,$N14)) | C14: =IF($N14="","",INDEX(Stats!$B$2:$B$26,$N14)) | D14: =IF($N14="","",INDEX(Stats!$M$2:$M$26,$N14)) | E14: =IF($N14="","",INDEX(Stats!$N$2:$N$26,$N14)) | F14: =IF($N14="","",INDEX(Stats!$O$2:$O$26,$N14)) | G14: =IF($N14="","",INDEX(Stats!$P$2:$P$26,$N14)) | H14: =IF($N14="","",INDEX(Stats!$Q$2:$Q$26,$N14)) | I14: =IF($N14="","",INDEX(Stats!$R$2:$R$26,$N14)) | J14: =IF($N14="","",INDEX(Stats!$S$2:$S$26,$N14)) | K14: =IF($N14="","",INDEX(Stats!$T$2:$T$26,$N14)) | M14: =IFERROR(LARGE(Stats!$V$2:$V$26,COUNTIF(Stats!$V$2:$V$26,">="&2*1000000000)+4),-1) | N14: =IF($M14>=1*1000000000,MATCH($M14,Stats!$V$2:$V$26,0),"")
A15: =IF($N15="","",5) | B15: =IF($N15="","",INDEX(Stats!$A$2:$A$26,$N15)) | C15: =IF($N15="","",INDEX(Stats!$B$2:$B$26,$N15)) | D15: =IF($N15="","",INDEX(Stats!$M$2:$M$26,$N15)) | E15: =IF($N15="","",INDEX(Stats!$N$2:$N$26,$N15)) | F15: =IF($N15="","",INDEX(Stats!$O$2:$O$26,$N15)) | G15: =IF($N15="","",INDEX(Stats!$P$2:$P$26,$N15)) | H15: =IF($N15="","",INDEX(Stats!$Q$2:$Q$26,$N15)) | I15: =IF($N15="","",INDEX(Stats!$R$2:$R$26,$N15)) | J15: =IF($N15="","",INDEX(Stats!$S$2:$S$26,$N15)) | K15: =IF($N15="","",INDEX(Stats!$T$2:$T$26,$N15)) | M15: =IFERROR(LARGE(Stats!$V$2:$V$26,COUNTIF(Stats!$V$2:$V$26,">="&2*1000000000)+5),-1) | N15: =IF($M15>=1*1000000000,MATCH($M15,Stats!$V$2:$V$26,0),"")
A16: =IF($N16="","",6) | B16: =IF($N16="","",INDEX(Stats!$A$2:$A$26,$N16)) | C16: =IF($N16="","",INDEX(Stats!$B$2:$B$26,$N16)) | D16: =IF($N16="","",INDEX(Stats!$M$2:$M$26,$N16)) | E16: =IF($N16="","",INDEX(Stats!$N$2:$N$26,$N16)) | F16: =IF($N16="","",INDEX(Stats!$O$2:$O$26,$N16)) | G16: =IF($N16="","",INDEX(Stats!$P$2:$P$26,$N16)) | H16: =IF($N16="","",INDEX(Stats!$Q$2:$Q$26,$N16)) | I16: =IF($N16="","",INDEX(Stats!$R$2:$R$26,$N16)) | J16: =IF($N16="","",INDEX(Stats!$S$2:$S$26,$N16)) | K16: =IF($N16="","",INDEX(Stats!$T$2:$T$26,$N16)) | M16: =IFERROR(LARGE(Stats!$V$2:$V$26,COUNTIF(Stats!$V$2:$V$26,">="&2*1000000000)+6),-1) | N16: =IF($M16>=1*1000000000,MATCH($M16,Stats!$V$2:$V$26,0),"")
A18: =IF(Settings!$A$16="","Group 2 (add the name on the Settings tab)",Settings!$A$16)
A19: Rank | B19: Player | C19: Group | D19: P | E19: W | F19: D | G19: L | H19: GF | I19: GA | J19: GD | K19: Pts
A20: =IF($N20="","",1) | B20: =IF($N20="","",INDEX(Stats!$A$2:$A$26,$N20)) | C20: =IF($N20="","",INDEX(Stats!$B$2:$B$26,$N20)) | D20: =IF($N20="","",INDEX(Stats!$M$2:$M$26,$N20)) | E20: =IF($N20="","",INDEX(Stats!$N$2:$N$26,$N20)) | F20: =IF($N20="","",INDEX(Stats!$O$2:$O$26,$N20)) | G20: =IF($N20="","",INDEX(Stats!$P$2:$P$26,$N20)) | H20: =IF($N20="","",INDEX(Stats!$Q$2:$Q$26,$N20)) | I20: =IF($N20="","",INDEX(Stats!$R$2:$R$26,$N20)) | J20: =IF($N20="","",INDEX(Stats!$S$2:$S$26,$N20)) | K20: =IF($N20="","",INDEX(Stats!$T$2:$T$26,$N20)) | M20: =IFERROR(LARGE(Stats!$V$2:$V$26,COUNTIF(Stats!$V$2:$V$26,">="&3*1000000000)+1),-1) | N20: =IF($M20>=2*1000000000,MATCH($M20,Stats!$V$2:$V$26,0),"")
A21: =IF($N21="","",2) | B21: =IF($N21="","",INDEX(Stats!$A$2:$A$26,$N21)) | C21: =IF($N21="","",INDEX(Stats!$B$2:$B$26,$N21)) | D21: =IF($N21="","",INDEX(Stats!$M$2:$M$26,$N21)) | E21: =IF($N21="","",INDEX(Stats!$N$2:$N$26,$N21)) | F21: =IF($N21="","",INDEX(Stats!$O$2:$O$26,$N21)) | G21: =IF($N21="","",INDEX(Stats!$P$2:$P$26,$N21)) | H21: =IF($N21="","",INDEX(Stats!$Q$2:$Q$26,$N21)) | I21: =IF($N21="","",INDEX(Stats!$R$2:$R$26,$N21)) | J21: =IF($N21="","",INDEX(Stats!$S$2:$S$26,$N21)) | K21: =IF($N21="","",INDEX(Stats!$T$2:$T$26,$N21)) | M21: =IFERROR(LARGE(Stats!$V$2:$V$26,COUNTIF(Stats!$V$2:$V$26,">="&3*1000000000)+2),-1) | N21: =IF($M21>=2*1000000000,MATCH($M21,Stats!$V$2:$V$26,0),"")
A22: =IF($N22="","",3) | B22: =IF($N22="","",INDEX(Stats!$A$2:$A$26,$N22)) | C22: =IF($N22="","",INDEX(Stats!$B$2:$B$26,$N22)) | D22: =IF($N22="","",INDEX(Stats!$M$2:$M$26,$N22)) | E22: =IF($N22="","",INDEX(Stats!$N$2:$N$26,$N22)) | F22: =IF($N22="","",INDEX(Stats!$O$2:$O$26,$N22)) | G22: =IF($N22="","",INDEX(Stats!$P$2:$P$26,$N22)) | H22: =IF($N22="","",INDEX(Stats!$Q$2:$Q$26,$N22)) | I22: =IF($N22="","",INDEX(Stats!$R$2:$R$26,$N22)) | J22: =IF($N22="","",INDEX(Stats!$S$2:$S$26,$N22)) | K22: =IF($N22="","",INDEX(Stats!$T$2:$T$26,$N22)) | M22: =IFERROR(LARGE(Stats!$V$2:$V$26,COUNTIF(Stats!$V$2:$V$26,">="&3*1000000000)+3),-1) | N22: =IF($M22>=2*1000000000,MATCH($M22,Stats!$V$2:$V$26,0),"")
A23: =IF($N23="","",4) | B23: =IF($N23="","",INDEX(Stats!$A$2:$A$26,$N23)) | C23: =IF($N23="","",INDEX(Stats!$B$2:$B$26,$N23)) | D23: =IF($N23="","",INDEX(Stats!$M$2:$M$26,$N23)) | E23: =IF($N23="","",INDEX(Stats!$N$2:$N$26,$N23)) | F23: =IF($N23="","",INDEX(Stats!$O$2:$O$26,$N23)) | G23: =IF($N23="","",INDEX(Stats!$P$2:$P$26,$N23)) | H23: =IF($N23="","",INDEX(Stats!$Q$2:$Q$26,$N23)) | I23: =IF($N23="","",INDEX(Stats!$R$2:$R$26,$N23)) | J23: =IF($N23="","",INDEX(Stats!$S$2:$S$26,$N23)) | K23: =IF($N23="","",INDEX(Stats!$T$2:$T$26,$N23)) | M23: =IFERROR(LARGE(Stats!$V$2:$V$26,COUNTIF(Stats!$V$2:$V$26,">="&3*1000000000)+4),-1) | N23: =IF($M23>=2*1000000000,MATCH($M23,Stats!$V$2:$V$26,0),"")
A24: =IF($N24="","",5) | B24: =IF($N24="","",INDEX(Stats!$A$2:$A$26,$N24)) | C24: =IF($N24="","",INDEX(Stats!$B$2:$B$26,$N24)) | D24: =IF($N24="","",INDEX(Stats!$M$2:$M$26,$N24)) | E24: =IF($N24="","",INDEX(Stats!$N$2:$N$26,$N24)) | F24: =IF($N24="","",INDEX(Stats!$O$2:$O$26,$N24)) | G24: =IF($N24="","",INDEX(Stats!$P$2:$P$26,$N24)) | H24: =IF($N24="","",INDEX(Stats!$Q$2:$Q$26,$N24)) | I24: =IF($N24="","",INDEX(Stats!$R$2:$R$26,$N24)) | J24: =IF($N24="","",INDEX(Stats!$S$2:$S$26,$N24)) | K24: =IF($N24="","",INDEX(Stats!$T$2:$T$26,$N24)) | M24: =IFERROR(LARGE(Stats!$V$2:$V$26,COUNTIF(Stats!$V$2:$V$26,">="&3*1000000000)+5),-1) | N24: =IF($M24>=2*1000000000,MATCH($M24,Stats!$V$2:$V$26,0),"")
A25: =IF($N25="","",6) | B25: =IF($N25="","",INDEX(Stats!$A$2:$A$26,$N25)) | C25: =IF($N25="","",INDEX(Stats!$B$2:$B$26,$N25)) | D25: =IF($N25="","",INDEX(Stats!$M$2:$M$26,$N25)) | E25: =IF($N25="","",INDEX(Stats!$N$2:$N$26,$N25)) | F25: =IF($N25="","",INDEX(Stats!$O$2:$O$26,$N25)) | G25: =IF($N25="","",INDEX(Stats!$P$2:$P$26,$N25)) | H25: =IF($N25="","",INDEX(Stats!$Q$2:$Q$26,$N25)) | I25: =IF($N25="","",INDEX(Stats!$R$2:$R$26,$N25)) | J25: =IF($N25="","",INDEX(Stats!$S$2:$S$26,$N25)) | K25: =IF($N25="","",INDEX(Stats!$T$2:$T$26,$N25)) | M25: =IFERROR(LARGE(Stats!$V$2:$V$26,COUNTIF(Stats!$V$2:$V$26,">="&3*1000000000)+6),-1) | N25: =IF($M25>=2*1000000000,MATCH($M25,Stats!$V$2:$V$26,0),"")
A27: =IF(Settings!$A$17="","Group 3 (add the name on the Settings tab)",Settings!$A$17)
A28: Rank | B28: Player | C28: Group | D28: P | E28: W | F28: D | G28: L | H28: GF | I28: GA | J28: GD | K28: Pts
A29: =IF($N29="","",1) | B29: =IF($N29="","",INDEX(Stats!$A$2:$A$26,$N29)) | C29: =IF($N29="","",INDEX(Stats!$B$2:$B$26,$N29)) | D29: =IF($N29="","",INDEX(Stats!$M$2:$M$26,$N29)) | E29: =IF($N29="","",INDEX(Stats!$N$2:$N$26,$N29)) | F29: =IF($N29="","",INDEX(Stats!$O$2:$O$26,$N29)) | G29: =IF($N29="","",INDEX(Stats!$P$2:$P$26,$N29)) | H29: =IF($N29="","",INDEX(Stats!$Q$2:$Q$26,$N29)) | I29: =IF($N29="","",INDEX(Stats!$R$2:$R$26,$N29)) | J29: =IF($N29="","",INDEX(Stats!$S$2:$S$26,$N29)) | K29: =IF($N29="","",INDEX(Stats!$T$2:$T$26,$N29)) | M29: =IFERROR(LARGE(Stats!$V$2:$V$26,COUNTIF(Stats!$V$2:$V$26,">="&4*1000000000)+1),-1) | N29: =IF($M29>=3*1000000000,MATCH($M29,Stats!$V$2:$V$26,0),"")
A30: =IF($N30="","",2) | B30: =IF($N30="","",INDEX(Stats!$A$2:$A$26,$N30)) | C30: =IF($N30="","",INDEX(Stats!$B$2:$B$26,$N30)) | D30: =IF($N30="","",INDEX(Stats!$M$2:$M$26,$N30)) | E30: =IF($N30="","",INDEX(Stats!$N$2:$N$26,$N30)) | F30: =IF($N30="","",INDEX(Stats!$O$2:$O$26,$N30)) | G30: =IF($N30="","",INDEX(Stats!$P$2:$P$26,$N30)) | H30: =IF($N30="","",INDEX(Stats!$Q$2:$Q$26,$N30)) | I30: =IF($N30="","",INDEX(Stats!$R$2:$R$26,$N30)) | J30: =IF($N30="","",INDEX(Stats!$S$2:$S$26,$N30)) | K30: =IF($N30="","",INDEX(Stats!$T$2:$T$26,$N30)) | M30: =IFERROR(LARGE(Stats!$V$2:$V$26,COUNTIF(Stats!$V$2:$V$26,">="&4*1000000000)+2),-1) | N30: =IF($M30>=3*1000000000,MATCH($M30,Stats!$V$2:$V$26,0),"")
A31: =IF($N31="","",3) | B31: =IF($N31="","",INDEX(Stats!$A$2:$A$26,$N31)) | C31: =IF($N31="","",INDEX(Stats!$B$2:$B$26,$N31)) | D31: =IF($N31="","",INDEX(Stats!$M$2:$M$26,$N31)) | E31: =IF($N31="","",INDEX(Stats!$N$2:$N$26,$N31)) | F31: =IF($N31="","",INDEX(Stats!$O$2:$O$26,$N31)) | G31: =IF($N31="","",INDEX(Stats!$P$2:$P$26,$N31)) | H31: =IF($N31="","",INDEX(Stats!$Q$2:$Q$26,$N31)) | I31: =IF($N31="","",INDEX(Stats!$R$2:$R$26,$N31)) | J31: =IF($N31="","",INDEX(Stats!$S$2:$S$26,$N31)) | K31: =IF($N31="","",INDEX(Stats!$T$2:$T$26,$N31)) | M31: =IFERROR(LARGE(Stats!$V$2:$V$26,COUNTIF(Stats!$V$2:$V$26,">="&4*1000000000)+3),-1) | N31: =IF($M31>=3*1000000000,MATCH($M31,Stats!$V$2:$V$26,0),"")
A32: =IF($N32="","",4) | B32: =IF($N32="","",INDEX(Stats!$A$2:$A$26,$N32)) | C32: =IF($N32="","",INDEX(Stats!$B$2:$B$26,$N32)) | D32: =IF($N32="","",INDEX(Stats!$M$2:$M$26,$N32)) | E32: =IF($N32="","",INDEX(Stats!$N$2:$N$26,$N32)) | F32: =IF($N32="","",INDEX(Stats!$O$2:$O$26,$N32)) | G32: =IF($N32="","",INDEX(Stats!$P$2:$P$26,$N32)) | H32: =IF($N32="","",INDEX(Stats!$Q$2:$Q$26,$N32)) | I32: =IF($N32="","",INDEX(Stats!$R$2:$R$26,$N32)) | J32: =IF($N32="","",INDEX(Stats!$S$2:$S$26,$N32)) | K32: =IF($N32="","",INDEX(Stats!$T$2:$T$26,$N32)) | M32: =IFERROR(LARGE(Stats!$V$2:$V$26,COUNTIF(Stats!$V$2:$V$26,">="&4*1000000000)+4),-1) | N32: =IF($M32>=3*1000000000,MATCH($M32,Stats!$V$2:$V$26,0),"")
A33: =IF($N33="","",5) | B33: =IF($N33="","",INDEX(Stats!$A$2:$A$26,$N33)) | C33: =IF($N33="","",INDEX(Stats!$B$2:$B$26,$N33)) | D33: =IF($N33="","",INDEX(Stats!$M$2:$M$26,$N33)) | E33: =IF($N33="","",INDEX(Stats!$N$2:$N$26,$N33)) | F33: =IF($N33="","",INDEX(Stats!$O$2:$O$26,$N33)) | G33: =IF($N33="","",INDEX(Stats!$P$2:$P$26,$N33)) | H33: =IF($N33="","",INDEX(Stats!$Q$2:$Q$26,$N33)) | I33: =IF($N33="","",INDEX(Stats!$R$2:$R$26,$N33)) | J33: =IF($N33="","",INDEX(Stats!$S$2:$S$26,$N33)) | K33: =IF($N33="","",INDEX(Stats!$T$2:$T$26,$N33)) | M33: =IFERROR(LARGE(Stats!$V$2:$V$26,COUNTIF(Stats!$V$2:$V$26,">="&4*1000000000)+5),-1) | N33: =IF($M33>=3*1000000000,MATCH($M33,Stats!$V$2:$V$26,0),"")
A34: =IF($N34="","",6) | B34: =IF($N34="","",INDEX(Stats!$A$2:$A$26,$N34)) | C34: =IF($N34="","",INDEX(Stats!$B$2:$B$26,$N34)) | D34: =IF($N34="","",INDEX(Stats!$M$2:$M$26,$N34)) | E34: =IF($N34="","",INDEX(Stats!$N$2:$N$26,$N34)) | F34: =IF($N34="","",INDEX(Stats!$O$2:$O$26,$N34)) | G34: =IF($N34="","",INDEX(Stats!$P$2:$P$26,$N34)) | H34: =IF($N34="","",INDEX(Stats!$Q$2:$Q$26,$N34)) | I34: =IF($N34="","",INDEX(Stats!$R$2:$R$26,$N34)) | J34: =IF($N34="","",INDEX(Stats!$S$2:$S$26,$N34)) | K34: =IF($N34="","",INDEX(Stats!$T$2:$T$26,$N34)) | M34: =IFERROR(LARGE(Stats!$V$2:$V$26,COUNTIF(Stats!$V$2:$V$26,">="&4*1000000000)+6),-1) | N34: =IF($M34>=3*1000000000,MATCH($M34,Stats!$V$2:$V$26,0),"")
A36: =IF(Settings!$A$18="","Group 4 (add the name on the Settings tab)",Settings!$A$18)
A37: Rank | B37: Player | C37: Group | D37: P | E37: W | F37: D | G37: L | H37: GF | I37: GA | J37: GD | K37: Pts
A38: =IF($N38="","",1) | B38: =IF($N38="","",INDEX(Stats!$A$2:$A$26,$N38)) | C38: =IF($N38="","",INDEX(Stats!$B$2:$B$26,$N38)) | D38: =IF($N38="","",INDEX(Stats!$M$2:$M$26,$N38)) | E38: =IF($N38="","",INDEX(Stats!$N$2:$N$26,$N38)) | F38: =IF($N38="","",INDEX(Stats!$O$2:$O$26,$N38)) | G38: =IF($N38="","",INDEX(Stats!$P$2:$P$26,$N38)) | H38: =IF($N38="","",INDEX(Stats!$Q$2:$Q$26,$N38)) | I38: =IF($N38="","",INDEX(Stats!$R$2:$R$26,$N38)) | J38: =IF($N38="","",INDEX(Stats!$S$2:$S$26,$N38)) | K38: =IF($N38="","",INDEX(Stats!$T$2:$T$26,$N38)) | M38: =IFERROR(LARGE(Stats!$V$2:$V$26,COUNTIF(Stats!$V$2:$V$26,">="&5*1000000000)+1),-1) | N38: =IF($M38>=4*1000000000,MATCH($M38,Stats!$V$2:$V$26,0),"")
A39: =IF($N39="","",2) | B39: =IF($N39="","",INDEX(Stats!$A$2:$A$26,$N39)) | C39: =IF($N39="","",INDEX(Stats!$B$2:$B$26,$N39)) | D39: =IF($N39="","",INDEX(Stats!$M$2:$M$26,$N39)) | E39: =IF($N39="","",INDEX(Stats!$N$2:$N$26,$N39)) | F39: =IF($N39="","",INDEX(Stats!$O$2:$O$26,$N39)) | G39: =IF($N39="","",INDEX(Stats!$P$2:$P$26,$N39)) | H39: =IF($N39="","",INDEX(Stats!$Q$2:$Q$26,$N39)) | I39: =IF($N39="","",INDEX(Stats!$R$2:$R$26,$N39)) | J39: =IF($N39="","",INDEX(Stats!$S$2:$S$26,$N39)) | K39: =IF($N39="","",INDEX(Stats!$T$2:$T$26,$N39)) | M39: =IFERROR(LARGE(Stats!$V$2:$V$26,COUNTIF(Stats!$V$2:$V$26,">="&5*1000000000)+2),-1) | N39: =IF($M39>=4*1000000000,MATCH($M39,Stats!$V$2:$V$26,0),"")
A40: =IF($N40="","",3) | B40: =IF($N40="","",INDEX(Stats!$A$2:$A$26,$N40)) | C40: =IF($N40="","",INDEX(Stats!$B$2:$B$26,$N40)) | D40: =IF($N40="","",INDEX(Stats!$M$2:$M$26,$N40)) | E40: =IF($N40="","",INDEX(Stats!$N$2:$N$26,$N40)) | F40: =IF($N40="","",INDEX(Stats!$O$2:$O$26,$N40)) | G40: =IF($N40="","",INDEX(Stats!$P$2:$P$26,$N40)) | H40: =IF($N40="","",INDEX(Stats!$Q$2:$Q$26,$N40)) | I40: =IF($N40="","",INDEX(Stats!$R$2:$R$26,$N40)) | J40: =IF($N40="","",INDEX(Stats!$S$2:$S$26,$N40)) | K40: =IF($N40="","",INDEX(Stats!$T$2:$T$26,$N40)) | M40: =IFERROR(LARGE(Stats!$V$2:$V$26,COUNTIF(Stats!$V$2:$V$26,">="&5*1000000000)+3),-1) | N40: =IF($M40>=4*1000000000,MATCH($M40,Stats!$V$2:$V$26,0),"")
A41: =IF($N41="","",4) | B41: =IF($N41="","",INDEX(Stats!$A$2:$A$26,$N41)) | C41: =IF($N41="","",INDEX(Stats!$B$2:$B$26,$N41)) | D41: =IF($N41="","",INDEX(Stats!$M$2:$M$26,$N41)) | E41: =IF($N41="","",INDEX(Stats!$N$2:$N$26,$N41)) | F41: =IF($N41="","",INDEX(Stats!$O$2:$O$26,$N41)) | G41: =IF($N41="","",INDEX(Stats!$P$2:$P$26,$N41)) | H41: =IF($N41="","",INDEX(Stats!$Q$2:$Q$26,$N41)) | I41: =IF($N41="","",INDEX(Stats!$R$2:$R$26,$N41)) | J41: =IF($N41="","",INDEX(Stats!$S$2:$S$26,$N41)) | K41: =IF($N41="","",INDEX(Stats!$T$2:$T$26,$N41)) | M41: =IFERROR(LARGE(Stats!$V$2:$V$26,COUNTIF(Stats!$V$2:$V$26,">="&5*1000000000)+4),-1) | N41: =IF($M41>=4*1000000000,MATCH($M41,Stats!$V$2:$V$26,0),"")
A42: =IF($N42="","",5) | B42: =IF($N42="","",INDEX(Stats!$A$2:$A$26,$N42)) | C42: =IF($N42="","",INDEX(Stats!$B$2:$B$26,$N42)) | D42: =IF($N42="","",INDEX(Stats!$M$2:$M$26,$N42)) | E42: =IF($N42="","",INDEX(Stats!$N$2:$N$26,$N42)) | F42: =IF($N42="","",INDEX(Stats!$O$2:$O$26,$N42)) | G42: =IF($N42="","",INDEX(Stats!$P$2:$P$26,$N42)) | H42: =IF($N42="","",INDEX(Stats!$Q$2:$Q$26,$N42)) | I42: =IF($N42="","",INDEX(Stats!$R$2:$R$26,$N42)) | J42: =IF($N42="","",INDEX(Stats!$S$2:$S$26,$N42)) | K42: =IF($N42="","",INDEX(Stats!$T$2:$T$26,$N42)) | M42: =IFERROR(LARGE(Stats!$V$2:$V$26,COUNTIF(Stats!$V$2:$V$26,">="&5*1000000000)+5),-1) | N42: =IF($M42>=4*1000000000,MATCH($M42,Stats!$V$2:$V$26,0),"")
A43: =IF($N43="","",6) | B43: =IF($N43="","",INDEX(Stats!$A$2:$A$26,$N43)) | C43: =IF($N43="","",INDEX(Stats!$B$2:$B$26,$N43)) | D43: =IF($N43="","",INDEX(Stats!$M$2:$M$26,$N43)) | E43: =IF($N43="","",INDEX(Stats!$N$2:$N$26,$N43)) | F43: =IF($N43="","",INDEX(Stats!$O$2:$O$26,$N43)) | G43: =IF($N43="","",INDEX(Stats!$P$2:$P$26,$N43)) | H43: =IF($N43="","",INDEX(Stats!$Q$2:$Q$26,$N43)) | I43: =IF($N43="","",INDEX(Stats!$R$2:$R$26,$N43)) | J43: =IF($N43="","",INDEX(Stats!$S$2:$S$26,$N43)) | K43: =IF($N43="","",INDEX(Stats!$T$2:$T$26,$N43)) | M43: =IFERROR(LARGE(Stats!$V$2:$V$26,COUNTIF(Stats!$V$2:$V$26,">="&5*1000000000)+6),-1) | N43: =IF($M43>=4*1000000000,MATCH($M43,Stats!$V$2:$V$26,0),"")
A45: FIFA overall (group and knockout matches)
...

Sheet Players
A1: Name | B1: Group | C1: Usual team | D1: Poker | E1: FIFA

Sheet Buy-ins
A1: Time | B1: Player | C1: Amount | D1: Recorded by

Sheet Matches
A1: Stage | B1: Round | C1: Player 1 | D1: Team 1 | E1: Goals 1 | F1: Goals 2 | G1: Team 2 | H1: Player 2 | I1: Status | J1: Won on penalties | K1: Winner | L1: Group | M1: Recorded by | N1: Live order
K2: =IF(OR(C2="",H2="",I2<>"Final"),"",IF(N(E2)>N(F2),C2,IF(N(F2)>N(E2),H2,IF(J2<>"",J2,"Draw")))) | L2: =IFERROR(IF(VLOOKUP(C2,Players!$A$2:$B$26,2,0)=VLOOKUP(H2,Players!$A$2:$B$26,2,0),VLOOKUP(C2,Players!$A$2:$B$26,2,0)&"",""),"") | N2: =IF(I2="Live",ROW(),"")
K3: =IF(OR(C3="",H3="",I3<>"Final"),"",IF(N(E3)>N(F3),C3,IF(N(F3)>N(E3),H3,IF(J3<>"",J3,"Draw")))) | L3: =IFERROR(IF(VLOOKUP(C3,Players!$A$2:$B$26,2,0)=VLOOKUP(H3,Players!$A$2:$B$26,2,0),VLOOKUP(C3,Players!$A$2:$B$26,2,0)&"",""),"") | N3: =IF(I3="Live",ROW(),"")
K4: =IF(OR(C4="",H4="",I4<>"Final"),"",IF(N(E4)>N(F4),C4,IF(N(F4)>N(E4),H4,IF(J4<>"",J4,"Draw")))) | L4: =IFERROR(IF(VLOOKUP(C4,Players!$A$2:$B$26,2,0)=VLOOKUP(H4,Players!$A$2:$B$26,2,0),VLOOKUP(C4,Players!$A$2:$B$26,2,0)&"",""),"") | N4: =IF(I4="Live",ROW(),"")
K5: =IF(OR(C5="",H5="",I5<>"Final"),"",IF(N(E5)>N(F5),C5,IF(N(F5)>N(E5),H5,IF(J5<>"",J5,"Draw")))) | L5: =IFERROR(IF(VLOOKUP(C5,Players!$A$2:$B$26,2,0)=VLOOKUP(H5,Players!$A$2:$B$26,2,0),VLOOKUP(C5,Players!$A$2:$B$26,2,0)&"",""),"") | N5: =IF(I5="Live",ROW(),"")
K6: =IF(OR(C6="",H6="",I6<>"Final"),"",IF(N(E6)>N(F6),C6,IF(N(F6)>N(E6),H6,IF(J6<>"",J6,"Draw")))) | L6: =IFERROR(IF(VLOOKUP(C6,Players!$A$2:$B$26,2,0)=VLOOKUP(H6,Players!$A$2:$B$26,2,0),VLOOKUP(C6,Players!$A$2:$B$26,2,0)&"",""),"") | N6: =IF(I6="Live",ROW(),"")
K7: =IF(OR(C7="",H7="",I7<>"Final"),"",IF(N(E7)>N(F7),C7,IF(N(F7)>N(E7),H7,IF(J7<>"",J7,"Draw")))) | L7: =IFERROR(IF(VLOOKUP(C7,Players!$A$2:$B$26,2,0)=VLOOKUP(H7,Players!$A$2:$B$26,2,0),VLOOKUP(C7,Players!$A$2:$B$26,2,0)&"",""),"") | N7: =IF(I7="Live",ROW(),"")
K8: =IF(OR(C8="",H8="",I8<>"Final"),"",IF(N(E8)>N(F8),C8,IF(N(F8)>N(E8),H8,IF(J8<>"",J8,"Draw")))) | L8: =IFERROR(IF(VLOOKUP(C8,Players!$A$2:$B$26,2,0)=VLOOKUP(H8,Players!$A$2:$B$26,2,0),VLOOKUP(C8,Players!$A$2:$B$26,2,0)&"",""),"") | N8: =IF(I8="Live",ROW(),"")
K9: =IF(OR(C9="",H9="",I9<>"Final"),"",IF(N(E9)>N(F9),C9,IF(N(F9)>N(E9),H9,IF(J9<>"",J9,"Draw")))) | L9: =IFERROR(IF(VLOOKUP(C9,Players!$A$2:$B$26,2,0)=VLOOKUP(H9,Players!$A$2:$B$26,2,0),VLOOKUP(C9,Players!$A$2:$B$26,2,0)&"",""),"") | N9: =IF(I9="Live",ROW(),"")
K10: =IF(OR(C10="",H10="",I10<>"Final"),"",IF(N(E10)>N(F10),C10,IF(N(F10)>N(E10),H10,IF(J10<>"",J10,"Draw")))) | L10: =IFERROR(IF(VLOOKUP(C10,Players!$A$2:$B$26,2,0)=VLOOKUP(H10,Players!$A$2:$B$26,2,0),VLOOKUP(C10,Players!$A$2:$B$26,2,0)&"",""),"") | N10: =IF(I10="Live",ROW(),"")
K11: =IF(OR(C11="",H11="",I11<>"Final"),"",IF(N(E11)>N(F11),C11,IF(N(F11)>N(E11),H11,IF(J11<>"",J11,"Draw")))) | L11: =IFERROR(IF(VLOOKUP(C11,Players!$A$2:$B$26,2,0)=VLOOKUP(H11,Players!$A$2:$B$26,2,0),VLOOKUP(C11,Players!$A$2:$B$26,2,0)&"",""),"") | N11: =IF(I11="Live",ROW(),"")
K12: =IF(OR(C12="",H12="",I12<>"Final"),"",IF(N(E12)>N(F12),C12,IF(N(F12)>N(E12),H12,IF(J12<>"",J12,"Draw")))) | L12: =IFERROR(IF(VLOOKUP(C12,Players!$A$2:$B$26,2,0)=VLOOKUP(H12,Players!$A$2:$B$26,2,0),VLOOKUP(C12,Players!$A$2:$B$26,2,0)&"",""),"") | N12: =IF(I12="Live",ROW(),"")
K13: =IF(OR(C13="",H13="",I13<>"Final"),"",IF(N(E13)>N(F13),C13,IF(N(F13)>N(E13),H13,IF(J13<>"",J13,"Draw")))) | L13: =IFERROR(IF(VLOOKUP(C13,Players!$A$2:$B$26,2,0)=VLOOKUP(H13,Players!$A$2:$B$26,2,0),VLOOKUP(C13,Players!$A$2:$B$26,2,0)&"",""),"") | N13: =IF(I13="Live",ROW(),"")
... K81: =IF(OR(C81="",H81="",I81<>"Final"),"",IF(N(E81)>N(F81),C81,IF(N(F81)>N(E81),H81,IF(J81<>"",J81,"Draw")))) | L81: =IFERROR(IF(VLOOKUP(C81,Players!$A$2:$B$26,2,0)=VLOOKUP(H81,Players!$A$2:$B$26,2,0),VLOOKUP(C81,Players!$A$2:$B$26,2,0)&"",""),"") | N81: =IF(I81="Live",ROW(),"")

Sheet Cash-out
A1: Player | B1: =Settings!A6&" ("&TEXT(Settings!B6,"$0.00")&")" | C1: =Settings!A7&" ("&TEXT(Settings!B7,"$0.00")&")" | D1: =Settings!A8&" ("&TEXT(Settings!B8,"$0.00")&")" | E1: =Settings!A9&" ("&TEXT(Settings!B9,"$0.00")&")" | F1: =Settings!A10&" ("&TEXT(Settings!B10,"$0.00")&")" | G1: Cash out | H1: Paid in | I1: Net | K1: Check
A2: =Stats!A2 | G2: =IF(COUNT(B2:F2)=0,"",B2*Settings!$B$6+C2*Settings!$B$7+D2*Settings!$B$8+E2*Settings!$B$9+F2*Settings!$B$10) | H2: =IF(A2="","",Stats!X2) | I2: =IF(G2="","",G2-H2) | K2: Total paid in | L2: =SUM(Stats!X2:X26)
A3: =Stats!A3 | G3: =IF(COUNT(B3:F3)=0,"",B3*Settings!$B$6+C3*Settings!$B$7+D3*Settings!$B$8+E3*Settings!$B$9+F3*Settings!$B$10) | H3: =IF(A3="","",Stats!X3) | I3: =IF(G3="","",G3-H3) | K3: Total cashed out | L3: =SUM(G2:G26)
A4: =Stats!A4 | G4: =IF(COUNT(B4:F4)=0,"",B4*Settings!$B$6+C4*Settings!$B$7+D4*Settings!$B$8+E4*Settings!$B$9+F4*Settings!$B$10) | H4: =IF(A4="","",Stats!X4) | I4: =IF(G4="","",G4-H4) | K4: Difference | L4: =L3-L2
A5: =Stats!A5 | G5: =IF(COUNT(B5:F5)=0,"",B5*Settings!$B$6+C5*Settings!$B$7+D5*Settings!$B$8+E5*Settings!$B$9+F5*Settings!$B$10) | H5: =IF(A5="","",Stats!X5) | I5: =IF(G5="","",G5-H5) | K5: =IF(COUNT(G2:G26)=0,"Enter chip counts to check.",IF(ABS(L4)<0.005,"Balanced.",IF(L4>0,"Too much cashed out. Recount.","Money is missing. Recount.")))
A6: =Stats!A6 | G6: =IF(COUNT(B6:F6)=0,"",B6*Settings!$B$6+C6*Settings!$B$7+D6*Settings!$B$8+E6*Settings!$B$9+F6*Settings!$B$10) | H6: =IF(A6="","",Stats!X6) | I6: =IF(G6="","",G6-H6)
A7: =Stats!A7 | G7: =IF(COUNT(B7:F7)=0,"",B7*Settings!$B$6+C7*Settings!$B$7+D7*Settings!$B$8+E7*Settings!$B$9+F7*Settings!$B$10) | H7: =IF(A7="","",Stats!X7) | I7: =IF(G7="","",G7-H7)
A8: =Stats!A8 | G8: =IF(COUNT(B8:F8)=0,"",B8*Settings!$B$6+C8*Settings!$B$7+D8*Settings!$B$8+E8*Settings!$B$9+F8*Settings!$B$10) | H8: =IF(A8="","",Stats!X8) | I8: =IF(G8="","",G8-H8)
A9: =Stats!A9 | G9: =IF(COUNT(B9:F9)=0,"",B9*Settings!$B$6+C9*Settings!$B$7+D9*Settings!$B$8+E9*Settings!$B$9+F9*Settings!$B$10) | H9: =IF(A9="","",Stats!X9) | I9: =IF(G9="","",G9-H9)
A10: =Stats!A10 | G10: =IF(COUNT(B10:F10)=0,"",B10*Settings!$B$6+C10*Settings!$B$7+D10*Settings!$B$8+E10*Settings!$B$9+F10*Settings!$B$10) | H10: =IF(A10="","",Stats!X10) | I10: =IF(G10="","",G10-H10)
A11: =Stats!A11 | G11: =IF(COUNT(B11:F11)=0,"",B11*Settings!$B$6+C11*Settings!$B$7+D11*Settings!$B$8+E11*Settings!$B$9+F11*Settings!$B$10) | H11: =IF(A11="","",Stats!X11) | I11: =IF(G11="","",G11-H11)
A12: =Stats!A12 | G12: =IF(COUNT(B12:F12)=0,"",B12*Settings!$B$6+C12*Settings!$B$7+D12*Settings!$B$8+E12*Settings!$B$9+F12*Settings!$B$10) | H12: =IF(A12="","",Stats!X12) | I12: =IF(G12="","",G12-H12)
A13: =Stats!A13 | G13: =IF(COUNT(B13:F13)=0,"",B13*Settings!$B$6+C13*Settings!$B$7+D13*Settings!$B$8+E13*Settings!$B$9+F13*Settings!$B$10) | H13: =IF(A13="","",Stats!X13) | I13: =IF(G13="","",G13-H13)
A14: =Stats!A14 | G14: =IF(COUNT(B14:F14)=0,"",B14*Settings!$B$6+C14*Settings!$B$7+D14*Settings!$B$8+E14*Settings!$B$9+F14*Settings!$B$10) | H14: =IF(A14="","",Stats!X14) | I14: =IF(G14="","",G14-H14)
A15: =Stats!A15 | G15: =IF(COUNT(B15:F15)=0,"",B15*Settings!$B$6+C15*Settings!$B$7+D15*Settings!$B$8+E15*Settings!$B$9+F15*Settings!$B$10) | H15: =IF(A15="","",Stats!X15) | I15: =IF(G15="","",G15-H15)
A16: =Stats!A16 | G16: =IF(COUNT(B16:F16)=0,"",B16*Settings!$B$6+C16*Settings!$B$7+D16*Settings!$B$8+E16*Settings!$B$9+F16*Settings!$B$10) | H16: =IF(A16="","",Stats!X16) | I16: =IF(G16="","",G16-H16)
A17: =Stats!A17 | G17: =IF(COUNT(B17:F17)=0,"",B17*Settings!$B$6+C17*Settings!$B$7+D17*Settings!$B$8+E17*Settings!$B$9+F17*Settings!$B$10) | H17: =IF(A17="","",Stats!X17) | I17: =IF(G17="","",G17-H17)
... A26: =Stats!A26 | G26: =IF(COUNT(B26:F26)=0,"",B26*Settings!$B$6+C26*Settings!$B$7+D26*Settings!$B$8+E26*Settings!$B$9+F26*Settings!$B$10) | H26: =IF(A26="","",Stats!X26) | I26: =IF(G26="","",G26-H26)

Sheet Settings
A1: Settings
A3: Standard buy-in | B3: 20
A5: Chip colour | B5: Value | C5: Chips per buy-in | D5: Value per buy-in
A6: White | B6: 0.1 | C6: 10 | D6: =B6*C6
A7: Red | B7: 0.2 | C7: 10 | D7: =B7*C7
A8: Green | B8: 0.5 | C8: 4 | D8: =B8*C8
A9: Purple | B9: 1 | C9: 10 | D9: =B9*C9
A10: Blue | B10: 5 | C10: 1 | D10: =B10*C10
A11: Starting stack | C11: =SUM(C6:C10) | D11: =SUM(D6:D10)
A12: =IF(ABS(D11-B3)<0.005,"The stack matches the buy-in.","The stack is worth "&TEXT(D11,"$0.00")&" but the buy-in is "&TEXT(B3,"$0.00")&".")
A13: Source: chip values and stack from the host, 17 Oct 2026.
A14: Groups (type the names)

Sheet Stats
A1: Name | B1: Group | C1: FIFA | D1: P | E1: W | F1: D | G1: L | H1: GF | I1: GA | J1: GD | K1: Pts | L1: Overall sort key | M1: Group P | N1: Group W | O1: Group D | P1: Group L | Q1: Group GF | R1: Group GA | S1: Group GD | T1: Group Pts | U1: Group no. | V1: Group sort key | W1: Buy-ins | X1: Paid in | Y1: Cash out | Z1: Net | AA1: Poker sort key | AC1: Helper calculations for the Leaderboard. Nothing to fill in here.
A2: =IF(TRIM(Players!A2)="","",TRIM(Players!A2)) | B2: =IF($A2="","",Players!B2&"") | C2: =Players!E2&"" | D2: =IF($A2="",0,COUNTIFS(Matches!$C:$C,$A2,Matches!$I:$I,"Final",Matches!$A:$A,"<>Friendly")+COUNTIFS(Matches!$H:$H,$A2,Matches!$I:$I,"Final",Matches!$A:$A,"<>Friendly")) | E2: =IF($A2="",0,COUNTIFS(Matches!$K:$K,$A2,Matches!$A:$A,"<>Friendly")) | F2: =IF($A2="",0,COUNTIFS(Matches!$C:$C,$A2,Matches!$K:$K,"Draw",Matches!$A:$A,"<>Friendly")+COUNTIFS(Matches!$H:$H,$A2,Matches!$K:$K,"Draw",Matches!$A:$A,"<>Friendly")) | G2: =D2-E2-F2 | H2: =IF($A2="",0,SUMIFS(Matches!$E:$E,Matches!$C:$C,$A2,Matches!$I:$I,"Final",Matches!$A:$A,"<>Friendly")+SUMIFS(Matches!$F:$F,Matches!$H:$H,$A2,Matches!$I:$I,"Final",Matches!$A:$A,"<>Friendly")) | I2: =IF($A2="",0,SUMIFS(Matches!$F:$F,Matches!$C:$C,$A2,Matches!$I:$I,"Final",Matches!$A:$A,"<>Friendly")+SUMIFS(Matches!$E:$E,Matches!$H:$H,$A2,Matches!$I:$I,"Final",Matches!$A:$A,"<>Friendly")) | J2: =H2-I2 | K2: =3*E2+F2 | L2: =IF(AND($A2<>"",OR($C2="Yes",D2>0)),K2*1000000+(MAX(-499,MIN(499,J2))+500)*1000+MIN(H2,99)*10+(50-ROW())/10,-1) | M2: =IF($B2="",0,COUNTIFS(Matches!$C:$C,$A2,Matches!$I:$I,"Final",Matches!$A:$A,"Group",Matches!$L:$L,$B2)+COUNTIFS(Matches!$H:$H,$A2,Matches!$I:$I,"Final",Matches!$A:$A,"Group",Matches!$L:$L,$B2)) | N2: =IF($B2="",0,COUNTIFS(Matches!$K:$K,$A2,Matches!$A:$A,"Group",Matches!$L:$L,$B2)) | O2: =IF($B2="",0,COUNTIFS(Matches!$C:$C,$A2,Matches!$K:$K,"Draw",Matches!$A:$A,"Group",Matches!$L:$L,$B2)+COUNTIFS(Matches!$H:$H,$A2,Matches!$K:$K,"Draw",Matches!$A:$A,"Group",Matches!$L:$L,$B2)) | P2: =M2-N2-O2 | Q2: =IF($B2="",0,SUMIFS(Matches!$E:$E,Matches!$C:$C,$A2,Matches!$I:$I,"Final",Matches!$A:$A,"Group",Matches!$L:$L,$B2)+SUMIFS(Matches!$F:$F,Matches!$H:$H,$A2,Matches!$I:$I,"Final",Matches!$A:$A,"Group",Matches!$L:$L,$B2)) | R2: =IF($B2="",0,SUMIFS(Matches!$F:$F,Matches!$C:$C,$A2,Matches!$I:$I,"Final",Matches!$A:$A,"Group",Matches!$L:$L,$B2)+SUMIFS(Matches!$E:$E,Matches!$H:$H,$A2,Matches!$I:$I,"Final",Matches!$A:$A,"Group",Matches!$L:$L,$B2)) | S2: =Q2-R2 | T2: =3*N2+O2 | U2: =IF($B2="",0,IFERROR(MATCH($B2,Settings!$A$15:$A$22,0),0)) | V2: =IF(OR($A2="",U2=0),-1,U2*1000000000+T2*1000000+(MAX(-499,MIN(499,S2))+500)*1000+MIN(Q2,99)*10+(50-ROW())/10) | W2: =IF($A2="",0,COUNTIF('Buy-ins'!$B:$B,$A2)) | X2: =IF($A2="",0,SUMIF('Buy-ins'!$B:$B,$A2,'Buy-ins'!$C:$C)+Settings!$B$3*COUNTIFS('Buy-ins'!$B:$B,$A2,'Buy-ins'!$C:$C,"")) | Y2: =IF($A2="","",'Cash-out'!G2) | Z2: =IF(OR($A2="",Y2=""),"",Y2-X2) | AA2: =IF(X2=0,-1,(IF(Z2="",0,Z2)+100000)*1000000+ROUND(X2*10,0)*10+(50-ROW())/10)
A3: =IF(TRIM(Players!A3)="","",TRIM(Players!A3)) | B3: =IF($A3="","",Players!B3&"") | C3: =Players!E3&"" | D3: =IF($A3="",0,COUNTIFS(Matches!$C:$C,$A3,Matches!$I:$I,"Final",Matches!$A:$A,"<>Friendly")+COUNTIFS(Matches!$H:$H,$A3,Matches!$I:$I,"Final",Matches!$A:$A,"<>Friendly")) | E3: =IF($A3="",0,COUNTIFS(Matches!$K:$K,$A3,Matches!$A:$A,"<>Friendly")) | F3: =IF($A3="",0,COUNTIFS(Matches!$C:$C,$A3,Matches!$K:$K,"Draw",Matches!$A:$A,"<>Friendly")+COUNTIFS(Matches!$H:$H,$A3,Matches!$K:$K,"Draw",Matches!$A:$A,"<>Friendly")) | G3: =D3-E3-F3 | H3: =IF($A3="",0,SUMIFS(Matches!$E:$E,Matches!$C:$C,$A3,Matches!$I:$I,"Final",Matches!$A:$A,"<>Friendly")+SUMIFS(Matches!$F:$F,Matches!$H:$H,$A3,Matches!$I:$I,"Final",Matches!$A:$A,"<>Friendly")) | I3: =IF($A3="",0,SUMIFS(Matches!$F:$F,Matches!$C:$C,$A3,Matches!$I:$I,"Final",Matches!$A:$A,"<>Friendly")+SUMIFS(Matches!$E:$E,Matches!$H:$H,$A3,Matches!$I:$I,"Final",Matches!$A:$A,"<>Friendly")) | J3: =H3-I3 | K3: =3*E3+F3 | L3: =IF(AND($A3<>"",OR($C3="Yes",D3>0)),K3*1000000+(MAX(-499,MIN(499,J3))+500)*1000+MIN(H3,99)*10+(50-ROW())/10,-1) | M3: =IF($B3="",0,COUNTIFS(Matches!$C:$C,$A3,Matches!$I:$I,"Final",Matches!$A:$A,"Group",Matches!$L:$L,$B3)+COUNTIFS(Matches!$H:$H,$A3,Matches!$I:$I,"Final",Matches!$A:$A,"Group",Matches!$L:$L,$B3)) | N3: =IF($B3="",0,COUNTIFS(Matches!$K:$K,$A3,Matches!$A:$A,"Group",Matches!$L:$L,$B3)) | O3: =IF($B3="",0,COUNTIFS(Matches!$C:$C,$A3,Matches!$K:$K,"Draw",Matches!$A:$A,"Group",Matches!$L:$L,$B3)+COUNTIFS(Matches!$H:$H,$A3,Matches!$K:$K,"Draw",Matches!$A:$A,"Group",Matches!$L:$L,$B3)) | P3: =M3-N3-O3 | Q3: =IF($B3="",0,SUMIFS(Matches!$E:$E,Matches!$C:$C,$A3,Matches!$I:$I,"Final",Matches!$A:$A,"Group",Matches!$L:$L,$B3)+SUMIFS(Matches!$F:$F,Matches!$H:$H,$A3,Matches!$I:$I,"Final",Matches!$A:$A,"Group",Matches!$L:$L,$B3)) | R3: =IF($B3="",0,SUMIFS(Matches!$F:$F,Matches!$C:$C,$A3,Matches!$I:$I,"Final",Matches!$A:$A,"Group",Matches!$L:$L,$B3)+SUMIFS(Matches!$E:$E,Matches!$H:$H,$A3,Matches!$I:$I,"Final",Matches!$A:$A,"Group",Matches!$L:$L,$B3)) | S3: =Q3-R3 | T3: =3*N3+O3 | U3: =IF($B3="",0,IFERROR(MATCH($B3,Settings!$A$15:$A$22,0),0)) | V3: =IF(OR($A3="",U3=0),-1,U3*1000000000+T3*1000000+(MAX(-499,MIN(499,S3))+500)*1000+MIN(Q3,99)*10+(50-ROW())/10) | W3: =IF($A3="",0,COUNTIF('Buy-ins'!$B:$B,$A3)) | X3: =IF($A3="",0,SUMIF('Buy-ins'!$B:$B,$A3,'Buy-ins'!$C:$C)+Settings!$B$3*COUNTIFS('Buy-ins'!$B:$B,$A3,'Buy-ins'!$C:$C,"")) | Y3: =IF($A3="","",'Cash-out'!G3) | Z3: =IF(OR($A3="",Y3=""),"",Y3-X3) | AA3: =IF(X3=0,-1,(IF(Z3="",0,Z3)+100000)*1000000+ROUND(X3*10,0)*10+(50-ROW())/10)
A4: =IF(TRIM(Players!A4)="","",TRIM(Players!A4)) | B4: =IF($A4="","",Players!B4&"") | C4: =Players!E4&"" | D4: =IF($A4="",0,COUNTIFS(Matches!$C:$C,$A4,Matches!$I:$I,"Final",Matches!$A:$A,"<>Friendly")+COUNTIFS(Matches!$H:$H,$A4,Matches!$I:$I,"Final",Matches!$A:$A,"<>Friendly")) | E4: =IF($A4="",0,COUNTIFS(Matches!$K:$K,$A4,Matches!$A:$A,"<>Friendly")) | F4: =IF($A4="",0,COUNTIFS(Matches!$C:$C,$A4,Matches!$K:$K,"Draw",Matches!$A:$A,"<>Friendly")+COUNTIFS(Matches!$H:$H,$A4,Matches!$K:$K,"Draw",Matches!$A:$A,"<>Friendly")) | G4: =D4-E4-F4 | H4: =IF($A4="",0,SUMIFS(Matches!$E:$E,Matches!$C:$C,$A4,Matches!$I:$I,"Final",Matches!$A:$A,"<>Friendly")+SUMIFS(Matches!$F:$F,Matches!$H:$H,$A4,Matches!$I:$I,"Final",Matches!$A:$A,"<>Friendly")) | I4: =IF($A4="",0,SUMIFS(Matches!$F:$F,Matches!$C:$C,$A4,Matches!$I:$I,"Final",Matches!$A:$A,"<>Friendly")+SUMIFS(Matches!$E:$E,Matches!$H:$H,$A4,Matches!$I:$I,"Final",Matches!$A:$A,"<>Friendly")) | J4: =H4-I4 | K4: =3*E4+F4 | L4: =IF(AND($A4<>"",OR($C4="Yes",D4>0)),K4*1000000+(MAX(-499,MIN(499,J4))+500)*1000+MIN(H4,99)*10+(50-ROW())/10,-1) | M4: =IF($B4="",0,COUNTIFS(Matches!$C:$C,$A4,Matches!$I:$I,"Final",Matches!$A:$A,"Group",Matches!$L:$L,$B4)+COUNTIFS(Matches!$H:$H,$A4,Matches!$I:$I,"Final",Matches!$A:$A,"Group",Matches!$L:$L,$B4)) | N4: =IF($B4="",0,COUNTIFS(Matches!$K:$K,$A4,Matches!$A:$A,"Group",Matches!$L:$L,$B4)) | O4: =IF($B4="",0,COUNTIFS(Matches!$C:$C,$A4,Matches!$K:$K,"Draw",Matches!$A:$A,"Group",Matches!$L:$L,$B4)+COUNTIFS(Matches!$H:$H,$A4,Matches!$K:$K,"Draw",Matches!$A:$A,"Group",Matches!$L:$L,$B4)) | P4: =M4-N4-O4 | Q4: =IF($B4="",0,SUMIFS(Matches!$E:$E,Matches!$C:$C,$A4,Matches!$I:$I,"Final",Matches!$A:$A,"Group",Matches!$L:$L,$B4)+SUMIFS(Matches!$F:$F,Matches!$H:$H,$A4,Matches!$I:$I,"Final",Matches!$A:$A,"Group",Matches!$L:$L,$B4)) | R4: =IF($B4="",0,SUMIFS(Matches!$F:$F,Matches!$C:$C,$A4,Matches!$I:$I,"Final",Matches!$A:$A,"Group",Matches!$L:$L,$B4)+SUMIFS(Matches!$E:$E,Matches!$H:$H,$A4,Matches!$I:$I,"Final",Matches!$A:$A,"Group",Matches!$L:$L,$B4)) | S4: =Q4-R4 | T4: =3*N4+O4 | U4: =IF($B4="",0,IFERROR(MATCH($B4,Settings!$A$15:$A$22,0),0)) | V4: =IF(OR($A4="",U4=0),-1,U4*1000000000+T4*1000000+(MAX(-499,MIN(499,S4))+500)*1000+MIN(Q4,99)*10+(50-ROW())/10) | W4: =IF($A4="",0,COUNTIF('Buy-ins'!$B:$B,$A4)) | X4: =IF($A4="",0,SUMIF('Buy-ins'!$B:$B,$A4,'Buy-ins'!$C:$C)+Settings!$B$3*COUNTIFS('Buy-ins'!$B:$B,$A4,'Buy-ins'!$C:$C,"")) | Y4: =IF($A4="","",'Cash-out'!G4) | Z4: =IF(OR($A4="",Y4=""),"",Y4-X4) | AA4: =IF(X4=0,-1,(IF(Z4="",0,Z4)+100000)*1000000+ROUND(X4*10,0)*10+(50-ROW())/10)
A5: =IF(TRIM(Players!A5)="","",TRIM(Players!A5)) | B5: =IF($A5="","",Players!B5&"") | C5: =Players!E5&"" | D5: =IF($A5="",0,COUNTIFS(Matches!$C:$C,$A5,Matches!$I:$I,"Final",Matches!$A:$A,"<>Friendly")+COUNTIFS(Matches!$H:$H,$A5,Matches!$I:$I,"Final",Matches!$A:$A,"<>Friendly")) | E5: =IF($A5="",0,COUNTIFS(Matches!$K:$K,$A5,Matches!$A:$A,"<>Friendly")) | F5: =IF($A5="",0,COUNTIFS(Matches!$C:$C,$A5,Matches!$K:$K,"Draw",Matches!$A:$A,"<>Friendly")+COUNTIFS(Matches!$H:$H,$A5,Matches!$K:$K,"Draw",Matches!$A:$A,"<>Friendly")) | G5: =D5-E5-F5 | H5: =IF($A5="",0,SUMIFS(Matches!$E:$E,Matches!$C:$C,$A5,Matches!$I:$I,"Final",Matches!$A:$A,"<>Friendly")+SUMIFS(Matches!$F:$F,Matches!$H:$H,$A5,Matches!$I:$I,"Final",Matches!$A:$A,"<>Friendly")) | I5: =IF($A5="",0,SUMIFS(Matches!$F:$F,Matches!$C:$C,$A5,Matches!$I:$I,"Final",Matches!$A:$A,"<>Friendly")+SUMIFS(Matches!$E:$E,Matches!$H:$H,$A5,Matches!$I:$I,"Final",Matches!$A:$A,"<>Friendly")) | J5: =H5-I5 | K5: =3*E5+F5 | L5: =IF(AND($A5<>"",OR($C5="Yes",D5>0)),K5*1000000+(MAX(-499,MIN(499,J5))+500)*1000+MIN(H5,99)*10+(50-ROW())/10,-1) | M5: =IF($B5="",0,COUNTIFS(Matches!$C:$C,$A5,Matches!$I:$I,"Final",Matches!$A:$A,"Group",Matches!$L:$L,$B5)+COUNTIFS(Matches!$H:$H,$A5,Matches!$I:$I,"Final",Matches!$A:$A,"Group",Matches!$L:$L,$B5)) | N5: =IF($B5="",0,COUNTIFS(Matches!$K:$K,$A5,Matches!$A:$A,"Group",Matches!$L:$L,$B5)) | O5: =IF($B5="",0,COUNTIFS(Matches!$C:$C,$A5,Matches!$K:$K,"Draw",Matches!$A:$A,"Group",Matches!$L:$L,$B5)+COUNTIFS(Matches!$H:$H,$A5,Matches!$K:$K,"Draw",Matches!$A:$A,"Group",Matches!$L:$L,$B5)) | P5: =M5-N5-O5 | Q5: =IF($B5="",0,SUMIFS(Matches!$E:$E,Matches!$C:$C,$A5,Matches!$I:$I,"Final",Matches!$A:$A,"Group",Matches!$L:$L,$B5)+SUMIFS(Matches!$F:$F,Matches!$H:$H,$A5,Matches!$I:$I,"Final",Matches!$A:$A,"Group",Matches!$L:$L,$B5)) | R5: =IF($B5="",0,SUMIFS(Matches!$F:$F,Matches!$C:$C,$A5,Matches!$I:$I,"Final",Matches!$A:$A,"Group",Matches!$L:$L,$B5)+SUMIFS(Matches!$E:$E,Matches!$H:$H,$A5,Matches!$I:$I,"Final",Matches!$A:$A,"Group",Matches!$L:$L,$B5)) | S5: =Q5-R5 | T5: =3*N5+O5 | U5: =IF($B5="",0,IFERROR(MATCH($B5,Settings!$A$15:$A$22,0),0)) | V5: =IF(OR($A5="",U5=0),-1,U5*1000000000+T5*1000000+(MAX(-499,MIN(499,S5))+500)*1000+MIN(Q5,99)*10+(50-ROW())/10) | W5: =IF($A5="",0,COUNTIF('Buy-ins'!$B:$B,$A5)) | X5: =IF($A5="",0,SUMIF('Buy-ins'!$B:$B,$A5,'Buy-ins'!$C:$C)+Settings!$B$3*COUNTIFS('Buy-ins'!$B:$B,$A5,'Buy-ins'!$C:$C,"")) | Y5: =IF($A5="","",'Cash-out'!G5) | Z5: =IF(OR($A5="",Y5=""),"",Y5-X5) | AA5: =IF(X5=0,-1,(IF(Z5="",0,Z5)+100000)*1000000+ROUND(X5*10,0)*10+(50-ROW())/10)
A6: =IF(TRIM(Players!A6)="","",TRIM(Players!A6)) | B6: =IF($A6="","",Players!B6&"") | C6: =Players!E6&"" | D6: =IF($A6="",0,COUNTIFS(Matches!$C:$C,$A6,Matches!$I:$I,"Final",Matches!$A:$A,"<>Friendly")+COUNTIFS(Matches!$H:$H,$A6,Matches!$I:$I,"Final",Matches!$A:$A,"<>Friendly")) | E6: =IF($A6="",0,COUNTIFS(Matches!$K:$K,$A6,Matches!$A:$A,"<>Friendly")) | F6: =IF($A6="",0,COUNTIFS(Matches!$C:$C,$A6,Matches!$K:$K,"Draw",Matches!$A:$A,"<>Friendly")+COUNTIFS(Matches!$H:$H,$A6,Matches!$K:$K,"Draw",Matches!$A:$A,"<>Friendly")) | G6: =D6-E6-F6 | H6: =IF($A6="",0,SUMIFS(Matches!$E:$E,Matches!$C:$C,$A6,Matches!$I:$I,"Final",Matches!$A:$A,"<>Friendly")+SUMIFS(Matches!$F:$F,Matches!$H:$H,$A6,Matches!$I:$I,"Final",Matches!$A:$A,"<>Friendly")) | I6: =IF($A6="",0,SUMIFS(Matches!$F:$F,Matches!$C:$C,$A6,Matches!$I:$I,"Final",Matches!$A:$A,"<>Friendly")+SUMIFS(Matches!$E:$E,Matches!$H:$H,$A6,Matches!$I:$I,"Final",Matches!$A:$A,"<>Friendly")) | J6: =H6-I6 | K6: =3*E6+F6 | L6: =IF(AND($A6<>"",OR($C6="Yes",D6>0)),K6*1000000+(MAX(-499,MIN(499,J6))+500)*1000+MIN(H6,99)*10+(50-ROW())/10,-1) | M6: =IF($B6="",0,COUNTIFS(Matches!$C:$C,$A6,Matches!$I:$I,"Final",Matches!$A:$A,"Group",Matches!$L:$L,$B6)+COUNTIFS(Matches!$H:$H,$A6,Matches!$I:$I,"Final",Matches!$A:$A,"Group",Matches!$L:$L,$B6)) | N6: =IF($B6="",0,COUNTIFS(Matches!$K:$K,$A6,Matches!$A:$A,"Group",Matches!$L:$L,$B6)) | O6: =IF($B6="",0,COUNTIFS(Matches!$C:$C,$A6,Matches!$K:$K,"Draw",Matches!$A:$A,"Group",Matches!$L:$L,$B6)+COUNTIFS(Matches!$H:$H,$A6,Matches!$K:$K,"Draw",Matches!$A:$A,"Group",Matches!$L:$L,$B6)) | P6: =M6-N6-O6 | Q6: =IF($B6="",0,SUMIFS(Matches!$E:$E,Matches!$C:$C,$A6,Matches!$I:$I,"Final",Matches!$A:$A,"Group",Matches!$L:$L,$B6)+SUMIFS(Matches!$F:$F,Matches!$H:$H,$A6,Matches!$I:$I,"Final",Matches!$A:$A,"Group",Matches!$L:$L,$B6)) | R6: =IF($B6="",0,SUMIFS(Matches!$F:$F,Matches!$C:$C,$A6,Matches!$I:$I,"Final",Matches!$A:$A,"Group",Matches!$L:$L,$B6)+SUMIFS(Matches!$E:$E,Matches!$H:$H,$A6,Matches!$I:$I,"Final",Matches!$A:$A,"Group",Matches!$L:$L,$B6)) | S6: =Q6-R6 | T6: =3*N6+O6 | U6: =IF($B6="",0,IFERROR(MATCH($B6,Settings!$A$15:$A$22,0),0)) | V6: =IF(OR($A6="",U6=0),-1,U6*1000000000+T6*1000000+(MAX(-499,MIN(499,S6))+500)*1000+MIN(Q6,99)*10+(50-ROW())/10) | W6: =IF($A6="",0,COUNTIF('Buy-ins'!$B:$B,$A6)) | X6: =IF($A6="",0,SUMIF('Buy-ins'!$B:$B,$A6,'Buy-ins'!$C:$C)+Settings!$B$3*COUNTIFS('Buy-ins'!$B:$B,$A6,'Buy-ins'!$C:$C,"")) | Y6: =IF($A6="","",'Cash-out'!G6) | Z6: =IF(OR($A6="",Y6=""),"",Y6-X6) | AA6: =IF(X6=0,-1,(IF(Z6="",0,Z6)+100000)*1000000+ROUND(X6*10,0)*10+(50-ROW())/10)
A7: =IF(TRIM(Players!A7)="","",TRIM(Players!A7)) | B7: =IF($A7="","",Players!B7&"") | C7: =Players!E7&"" | D7: =IF($A7="",0,COUNTIFS(Matches!$C:$C,$A7,Matches!$I:$I,"Final",Matches!$A:$A,"<>Friendly")+COUNTIFS(Matches!$H:$H,$A7,Matches!$I:$I,"Final",Matches!$A:$A,"<>Friendly")) | E7: =IF($A7="",0,COUNTIFS(Matches!$K:$K,$A7,Matches!$A:$A,"<>Friendly")) | F7: =IF($A7="",0,COUNTIFS(Matches!$C:$C,$A7,Matches!$K:$K,"Draw",Matches!$A:$A,"<>Friendly")+COUNTIFS(Matches!$H:$H,$A7,Matches!$K:$K,"Draw",Matches!$A:$A,"<>Friendly")) | G7: =D7-E7-F7 | H7: =IF($A7="",0,SUMIFS(Matches!$E:$E,Matches!$C:$C,$A7,Matches!$I:$I,"Final",Matches!$A:$A,"<>Friendly")+SUMIFS(Matches!$F:$F,Matches!$H:$H,$A7,Matches!$I:$I,"Final",Matches!$A:$A,"<>Friendly")) | I7: =IF($A7="",0,SUMIFS(Matches!$F:$F,Matches!$C:$C,$A7,Matches!$I:$I,"Final",Matches!$A:$A,"<>Friendly")+SUMIFS(Matches!$E:$E,Matches!$H:$H,$A7,Matches!$I:$I,"Final",Matches!$A:$A,"<>Friendly")) | J7: =H7-I7 | K7: =3*E7+F7 | L7: =IF(AND($A7<>"",OR($C7="Yes",D7>0)),K7*1000000+(MAX(-499,MIN(499,J7))+500)*1000+MIN(H7,99)*10+(50-ROW())/10,-1) | M7: =IF($B7="",0,COUNTIFS(Matches!$C:$C,$A7,Matches!$I:$I,"Final",Matches!$A:$A,"Group",Matches!$L:$L,$B7)+COUNTIFS(Matches!$H:$H,$A7,Matches!$I:$I,"Final",Matches!$A:$A,"Group",Matches!$L:$L,$B7)) | N7: =IF($B7="",0,COUNTIFS(Matches!$K:$K,$A7,Matches!$A:$A,"Group",Matches!$L:$L,$B7)) | O7: =IF($B7="",0,COUNTIFS(Matches!$C:$C,$A7,Matches!$K:$K,"Draw",Matches!$A:$A,"Group",Matches!$L:$L,$B7)+COUNTIFS(Matches!$H:$H,$A7,Matches!$K:$K,"Draw",Matches!$A:$A,"Group",Matches!$L:$L,$B7)) | P7: =M7-N7-O7 | Q7: =IF($B7="",0,SUMIFS(Matches!$E:$E,Matches!$C:$C,$A7,Matches!$I:$I,"Final",Matches!$A:$A,"Group",Matches!$L:$L,$B7)+SUMIFS(Matches!$F:$F,Matches!$H:$H,$A7,Matches!$I:$I,"Final",Matches!$A:$A,"Group",Matches!$L:$L,$B7)) | R7: =IF($B7="",0,SUMIFS(Matches!$F:$F,Matches!$C:$C,$A7,Matches!$I:$I,"Final",Matches!$A:$A,"Group",Matches!$L:$L,$B7)+SUMIFS(Matches!$E:$E,Matches!$H:$H,$A7,Matches!$I:$I,"Final",Matches!$A:$A,"Group",Matches!$L:$L,$B7)) | S7: =Q7-R7 | T7: =3*N7+O7 | U7: =IF($B7="",0,IFERROR(MATCH($B7,Settings!$A$15:$A$22,0),0)) | V7: =IF(OR($A7="",U7=0),-1,U7*1000000000+T7*1000000+(MAX(-499,MIN(499,S7))+500)*1000+MIN(Q7,99)*10+(50-ROW())/10) | W7: =IF($A7="",0,COUNTIF('Buy-ins'!$B:$B,$A7)) | X7: =IF($A7="",0,SUMIF('Buy-ins'!$B:$B,$A7,'Buy-ins'!$C:$C)+Settings!$B$3*COUNTIFS('Buy-ins'!$B:$B,$A7,'Buy-ins'!$C:$C,"")) | Y7: =IF($A7="","",'Cash-out'!G7) | Z7: =IF(OR($A7="",Y7=""),"",Y7-X7) | AA7: =IF(X7=0,-1,(IF(Z7="",0,Z7)+100000)*1000000+ROUND(X7*10,0)*10+(50-ROW())/10)
A8: =IF(TRIM(Players!A8)="","",TRIM(Players!A8)) | B8: =IF($A8="","",Players!B8&"") | C8: =Players!E8&"" | D8: =IF($A8="",0,COUNTIFS(Matches!$C:$C,$A8,Matches!$I:$I,"Final",Matches!$A:$A,"<>Friendly")+COUNTIFS(Matches!$H:$H,$A8,Matches!$I:$I,"Final",Matches!$A:$A,"<>Friendly")) | E8: =IF($A8="",0,COUNTIFS(Matches!$K:$K,$A8,Matches!$A:$A,"<>Friendly")) | F8: =IF($A8="",0,COUNTIFS(Matches!$C:$C,$A8,Matches!$K:$K,"Draw",Matches!$A:$A,"<>Friendly")+COUNTIFS(Matches!$H:$H,$A8,Matches!$K:$K,"Draw",Matches!$A:$A,"<>Friendly")) | G8: =D8-E8-F8 | H8: =IF($A8="",0,SUMIFS(Matches!$E:$E,Matches!$C:$C,$A8,Matches!$I:$I,"Final",Matches!$A:$A,"<>Friendly")+SUMIFS(Matches!$F:$F,Matches!$H:$H,$A8,Matches!$I:$I,"Final",Matches!$A:$A,"<>Friendly")) | I8: =IF($A8="",0,SUMIFS(Matches!$F:$F,Matches!$C:$C,$A8,Matches!$I:$I,"Final",Matches!$A:$A,"<>Friendly")+SUMIFS(Matches!$E:$E,Matches!$H:$H,$A8,Matches!$I:$I,"Final",Matches!$A:$A,"<>Friendly")) | J8: =H8-I8 | K8: =3*E8+F8 | L8: =IF(AND($A8<>"",OR($C8="Yes",D8>0)),K8*1000000+(MAX(-499,MIN(499,J8))+500)*1000+MIN(H8,99)*10+(50-ROW())/10,-1) | M8: =IF($B8="",0,COUNTIFS(Matches!$C:$C,$A8,Matches!$I:$I,"Final",Matches!$A:$A,"Group",Matches!$L:$L,$B8)+COUNTIFS(Matches!$H:$H,$A8,Matches!$I:$I,"Final",Matches!$A:$A,"Group",Matches!$L:$L,$B8)) | N8: =IF($B8="",0,COUNTIFS(Matches!$K:$K,$A8,Matches!$A:$A,"Group",Matches!$L:$L,$B8)) | O8: =IF($B8="",0,COUNTIFS(Matches!$C:$C,$A8,Matches!$K:$K,"Draw",Matches!$A:$A,"Group",Matches!$L:$L,$B8)+COUNTIFS(Matches!$H:$H,$A8,Matches!$K:$K,"Draw",Matches!$A:$A,"Group",Matches!$L:$L,$B8)) | P8: =M8-N8-O8 | Q8: =IF($B8="",0,SUMIFS(Matches!$E:$E,Matches!$C:$C,$A8,Matches!$I:$I,"Final",Matches!$A:$A,"Group",Matches!$L:$L,$B8)+SUMIFS(Matches!$F:$F,Matches!$H:$H,$A8,Matches!$I:$I,"Final",Matches!$A:$A,"Group",Matches!$L:$L,$B8)) | R8: =IF($B8="",0,SUMIFS(Matches!$F:$F,Matches!$C:$C,$A8,Matches!$I:$I,"Final",Matches!$A:$A,"Group",Matches!$L:$L,$B8)+SUMIFS(Matches!$E:$E,Matches!$H:$H,$A8,Matches!$I:$I,"Final",Matches!$A:$A,"Group",Matches!$L:$L,$B8)) | S8: =Q8-R8 | T8: =3*N8+O8 | U8: =IF($B8="",0,IFERROR(MATCH($B8,Settings!$A$15:$A$22,0),0)) | V8: =IF(OR($A8="",U8=0),-1,U8*1000000000+T8*1000000+(MAX(-499,MIN(499,S8))+500)*1000+MIN(Q8,99)*10+(50-ROW())/10) | W8: =IF($A8="",0,COUNTIF('Buy-ins'!$B:$B,$A8)) | X8: =IF($A8="",0,SUMIF('Buy-ins'!$B:$B,$A8,'Buy-ins'!$C:$C)+Settings!$B$3*COUNTIFS('Buy-ins'!$B:$B,$A8,'Buy-ins'!$C:$C,"")) | Y8: =IF($A8="","",'Cash-out'!G8) | Z8: =IF(OR($A8="",Y8=""),"",Y8-X8) | AA8: =IF(X8=0,-1,(IF(Z8="",0,Z8)+100000)*1000000+ROUND(X8*10,0)*10+(50-ROW())/10)
A9: =IF(TRIM(Players!A9)="","",TRIM(Players!A9)) | B9: =IF($A9="","",Players!B9&"") | C9: =Players!E9&"" | D9: =IF($A9="",0,COUNTIFS(Matches!$C:$C,$A9,Matches!$I:$I,"Final",Matches!$A:$A,"<>Friendly")+COUNTIFS(Matches!$H:$H,$A9,Matches!$I:$I,"Final",Matches!$A:$A,"<>Friendly")) | E9: =IF($A9="",0,COUNTIFS(Matches!$K:$K,$A9,Matches!$A:$A,"<>Friendly")) | F9: =IF($A9="",0,COUNTIFS(Matches!$C:$C,$A9,Matches!$K:$K,"Draw",Matches!$A:$A,"<>Friendly")+COUNTIFS(Matches!$H:$H,$A9,Matches!$K:$K,"Draw",Matches!$A:$A,"<>Friendly")) | G9: =D9-E9-F9 | H9: =IF($A9="",0,SUMIFS(Matches!$E:$E,Matches!$C:$C,$A9,Matches!$I:$I,"Final",Matches!$A:$A,"<>Friendly")+SUMIFS(Matches!$F:$F,Matches!$H:$H,$A9,Matches!$I:$I,"Final",Matches!$A:$A,"<>Friendly")) | I9: =IF($A9="",0,SUMIFS(Matches!$F:$F,Matches!$C:$C,$A9,Matches!$I:$I,"Final",Matches!$A:$A,"<>Friendly")+SUMIFS(Matches!$E:$E,Matches!$H:$H,$A9,Matches!$I:$I,"Final",Matches!$A:$A,"<>Friendly")) | J9: =H9-I9 | K9: =3*E9+F9 | L9: =IF(AND($A9<>"",OR($C9="Yes",D9>0)),K9*1000000+(MAX(-499,MIN(499,J9))+500)*1000+MIN(H9,99)*10+(50-ROW())/10,-1) | M9: =IF($B9="",0,COUNTIFS(Matches!$C:$C,$A9,Matches!$I:$I,"Final",Matches!$A:$A,"Group",Matches!$L:$L,$B9)+COUNTIFS(Matches!$H:$H,$A9,Matches!$I:$I,"Final",Matches!$A:$A,"Group",Matches!$L:$L,$B9)) | N9: =IF($B9="",0,COUNTIFS(Matches!$K:$K,$A9,Matches!$A:$A,"Group",Matches!$L:$L,$B9)) | O9: =IF($B9="",0,COUNTIFS(Matches!$C:$C,$A9,Matches!$K:$K,"Draw",Matches!$A:$A,"Group",Matches!$L:$L,$B9)+COUNTIFS(Matches!$H:$H,$A9,Matches!$K:$K,"Draw",Matches!$A:$A,"Group",Matches!$L:$L,$B9)) | P9: =M9-N9-O9 | Q9: =IF($B9="",0,SUMIFS(Matches!$E:$E,Matches!$C:$C,$A9,Matches!$I:$I,"Final",Matches!$A:$A,"Group",Matches!$L:$L,$B9)+SUMIFS(Matches!$F:$F,Matches!$H:$H,$A9,Matches!$I:$I,"Final",Matches!$A:$A,"Group",Matches!$L:$L,$B9)) | R9: =IF($B9="",0,SUMIFS(Matches!$F:$F,Matches!$C:$C,$A9,Matches!$I:$I,"Final",Matches!$A:$A,"Group",Matches!$L:$L,$B9)+SUMIFS(Matches!$E:$E,Matches!$H:$H,$A9,Matches!$I:$I,"Final",Matches!$A:$A,"Group",Matches!$L:$L,$B9)) | S9: =Q9-R9 | T9: =3*N9+O9 | U9: =IF($B9="",0,IFERROR(MATCH($B9,Settings!$A$15:$A$22,0),0)) | V9: =IF(OR($A9="",U9=0),-1,U9*1000000000+T9*1000000+(MAX(-499,MIN(499,S9))+500)*1000+MIN(Q9,99)*10+(50-ROW())/10) | W9: =IF($A9="",0,COUNTIF('Buy-ins'!$B:$B,$A9)) | X9: =IF($A9="",0,SUMIF('Buy-ins'!$B:$B,$A9,'Buy-ins'!$C:$C)+Settings!$B$3*COUNTIFS('Buy-ins'!$B:$B,$A9,'Buy-ins'!$C:$C,"")) | Y9: =IF($A9="","",'Cash-out'!G9) | Z9: =IF(OR($A9="",Y9=""),"",Y9-X9) | AA9: =IF(X9=0,-1,(IF(Z9="",0,Z9)+100000)*1000000+ROUND(X9*10,0)*10+(50-ROW())/10)
A10: =IF(TRIM(Players!A10)="","",TRIM(Players!A10)) | B10: =IF($A10="","",Players!B10&"") | C10: =Players!E10&"" | D10: =IF($A10="",0,COUNTIFS(Matches!$C:$C,$A10,Matches!$I:$I,"Final",Matches!$A:$A,"<>Friendly")+COUNTIFS(Matches!$H:$H,$A10,Matches!$I:$I,"Final",Matches!$A:$A,"<>Friendly")) | E10: =IF($A10="",0,COUNTIFS(Matches!$K:$K,$A10,Matches!$A:$A,"<>Friendly")) | F10: =IF($A10="",0,COUNTIFS(Matches!$C:$C,$A10,Matches!$K:$K,"Draw",Matches!$A:$A,"<>Friendly")+COUNTIFS(Matches!$H:$H,$A10,Matches!$K:$K,"Draw",Matches!$A:$A,"<>Friendly")) | G10: =D10-E10-F10 | H10: =IF($A10="",0,SUMIFS(Matches!$E:$E,Matches!$C:$C,$A10,Matches!$I:$I,"Final",Matches!$A:$A,"<>Friendly")+SUMIFS(Matches!$F:$F,Matches!$H:$H,$A10,Matches!$I:$I,"Final",Matches!$A:$A,"<>Friendly")) | I10: =IF($A10="",0,SUMIFS(Matches!$F:$F,Matches!$C:$C,$A10,Matches!$I:$I,"Final",Matches!$A:$A,"<>Friendly")+SUMIFS(Matches!$E:$E,Matches!$H:$H,$A10,Matches!$I:$I,"Final",Matches!$A:$A,"<>Friendly")) | J10: =H10-I10 | K10: =3*E10+F10 | L10: =IF(AND($A10<>"",OR($C10="Yes",D10>0)),K10*1000000+(MAX(-499,MIN(499,J10))+500)*1000+MIN(H10,99)*10+(50-ROW())/10,-1) | M10: =IF($B10="",0,COUNTIFS(Matches!$C:$C,$A10,Matches!$I:$I,"Final",Matches!$A:$A,"Group",Matches!$L:$L,$B10)+COUNTIFS(Matches!$H:$H,$A10,Matches!$I:$I,"Final",Matches!$A:$A,"Group",Matches!$L:$L,$B10)) | N10: =IF($B10="",0,COUNTIFS(Matches!$K:$K,$A10,Matches!$A:$A,"Group",Matches!$L:$L,$B10)) | O10: =IF($B10="",0,COUNTIFS(Matches!$C:$C,$A10,Matches!$K:$K,"Draw",Matches!$A:$A,"Group",Matches!$L:$L,$B10)+COUNTIFS(Matches!$H:$H,$A10,Matches!$K:$K,"Draw",Matches!$A:$A,"Group",Matches!$L:$L,$B10)) | P10: =M10-N10-O10 | Q10: =IF($B10="",0,SUMIFS(Matches!$E:$E,Matches!$C:$C,$A10,Matches!$I:$I,"Final",Matches!$A:$A,"Group",Matches!$L:$L,$B10)+SUMIFS(Matches!$F:$F,Matches!$H:$H,$A10,Matches!$I:$I,"Final",Matches!$A:$A,"Group",Matches!$L:$L,$B10)) | R10: =IF($B10="",0,SUMIFS(Matches!$F:$F,Matches!$C:$C,$A10,Matches!$I:$I,"Final",Matches!$A:$A,"Group",Matches!$L:$L,$B10)+SUMIFS(Matches!$E:$E,Matches!$H:$H,$A10,Matches!$I:$I,"Final",Matches!$A:$A,"Group",Matches!$L:$L,$B10)) | S10: =Q10-R10 | T10: =3*N10+O10 | U10: =IF($B10="",0,IFERROR(MATCH($B10,Settings!$A$15:$A$22,0),0)) | V10: =IF(OR($A10="",U10=0),-1,U10*1000000000+T10*1000000+(MAX(-499,MIN(499,S10))+500)*1000+MIN(Q10,99)*10+(50-ROW())/10) | W10: =IF($A10="",0,COUNTIF('Buy-ins'!$B:$B,$A10)) | X10: =IF($A10="",0,SUMIF('Buy-ins'!$B:$B,$A10,'Buy-ins'!$C:$C)+Settings!$B$3*COUNTIFS('Buy-ins'!$B:$B,$A10,'Buy-ins'!$C:$C,"")) | Y10: =IF($A10="","",'Cash-out'!G10) | Z10: =IF(OR($A10="",Y10=""),"",Y10-X10) | AA10: =IF(X10=0,-1,(IF(Z10="",0,Z10)+100000)*1000000+ROUND(X10*10,0)*10+(50-ROW())/10)
A11: =IF(TRIM(Players!A11)="","",TRIM(Players!A11)) | B11: =IF($A11="","",Players!B11&"") | C11: =Players!E11&"" | D11: =IF($A11="",0,COUNTIFS(Matches!$C:$C,$A11,Matches!$I:$I,"Final",Matches!$A:$A,"<>Friendly")+COUNTIFS(Matches!$H:$H,$A11,Matches!$I:$I,"Final",Matches!$A:$A,"<>Friendly")) | E11: =IF($A11="",0,COUNTIFS(Matches!$K:$K,$A11,Matches!$A:$A,"<>Friendly")) | F11: =IF($A11="",0,COUNTIFS(Matches!$C:$C,$A11,Matches!$K:$K,"Draw",Matches!$A:$A,"<>Friendly")+COUNTIFS(Matches!$H:$H,$A11,Matches!$K:$K,"Draw",Matches!$A:$A,"<>Friendly")) | G11: =D11-E11-F11 | H11: =IF($A11="",0,SUMIFS(Matches!$E:$E,Matches!$C:$C,$A11,Matches!$I:$I,"Final",Matches!$A:$A,"<>Friendly")+SUMIFS(Matches!$F:$F,Matches!$H:$H,$A11,Matches!$I:$I,"Final",Matches!$A:$A,"<>Friendly")) | I11: =IF($A11="",0,SUMIFS(Matches!$F:$F,Matches!$C:$C,$A11,Matches!$I:$I,"Final",Matches!$A:$A,"<>Friendly")+SUMIFS(Matches!$E:$E,Matches!$H:$H,$A11,Matches!$I:$I,"Final",Matches!$A:$A,"<>Friendly")) | J11: =H11-I11 | K11: =3*E11+F11 | L11: =IF(AND($A11<>"",OR($C11="Yes",D11>0)),K11*1000000+(MAX(-499,MIN(499,J11))+500)*1000+MIN(H11,99)*10+(50-ROW())/10,-1) | M11: =IF($B11="",0,COUNTIFS(Matches!$C:$C,$A11,Matches!$I:$I,"Final",Matches!$A:$A,"Group",Matches!$L:$L,$B11)+COUNTIFS(Matches!$H:$H,$A11,Matches!$I:$I,"Final",Matches!$A:$A,"Group",Matches!$L:$L,$B11)) | N11: =IF($B11="",0,COUNTIFS(Matches!$K:$K,$A11,Matches!$A:$A,"Group",Matches!$L:$L,$B11)) | O11: =IF($B11="",0,COUNTIFS(Matches!$C:$C,$A11,Matches!$K:$K,"Draw",Matches!$A:$A,"Group",Matches!$L:$L,$B11)+COUNTIFS(Matches!$H:$H,$A11,Matches!$K:$K,"Draw",Matches!$A:$A,"Group",Matches!$L:$L,$B11)) | P11: =M11-N11-O11 | Q11: =IF($B11="",0,SUMIFS(Matches!$E:$E,Matches!$C:$C,$A11,Matches!$I:$I,"Final",Matches!$A:$A,"Group",Matches!$L:$L,$B11)+SUMIFS(Matches!$F:$F,Matches!$H:$H,$A11,Matches!$I:$I,"Final",Matches!$A:$A,"Group",Matches!$L:$L,$B11)) | R11: =IF($B11="",0,SUMIFS(Matches!$F:$F,Matches!$C:$C,$A11,Matches!$I:$I,"Final",Matches!$A:$A,"Group",Matches!$L:$L,$B11)+SUMIFS(Matches!$E:$E,Matches!$H:$H,$A11,Matches!$I:$I,"Final",Matches!$A:$A,"Group",Matches!$L:$L,$B11)) | S11: =Q11-R11 | T11: =3*N11+O11 | U11: =IF($B11="",0,IFERROR(MATCH($B11,Settings!$A$15:$A$22,0),0)) | V11: =IF(OR($A11="",U11=0),-1,U11*1000000000+T11*1000000+(MAX(-499,MIN(499,S11))+500)*1000+MIN(Q11,99)*10+(50-ROW())/10) | W11: =IF($A11="",0,COUNTIF('Buy-ins'!$B:$B,$A11)) | X11: =IF($A11="",0,SUMIF('Buy-ins'!$B:$B,$A11,'Buy-ins'!$C:$C)+Settings!$B$3*COUNTIFS('Buy-ins'!$B:$B,$A11,'Buy-ins'!$C:$C,"")) | Y11: =IF($A11="","",'Cash-out'!G11) | Z11: =IF(OR($A11="",Y11=""),"",Y11-X11) | AA11: =IF(X11=0,-1,(IF(Z11="",0,Z11)+100000)*1000000+ROUND(X11*10,0)*10+(50-ROW())/10)
A12: =IF(TRIM(Players!A12)="","",TRIM(Players!A12)) | B12: =IF($A12="","",Players!B12&"") | C12: =Players!E12&"" | D12: =IF($A12="",0,COUNTIFS(Matches!$C:$C,$A12,Matches!$I:$I,"Final",Matches!$A:$A,"<>Friendly")+COUNTIFS(Matches!$H:$H,$A12,Matches!$I:$I,"Final",Matches!$A:$A,"<>Friendly")) | E12: =IF($A12="",0,COUNTIFS(Matches!$K:$K,$A12,Matches!$A:$A,"<>Friendly")) | F12: =IF($A12="",0,COUNTIFS(Matches!$C:$C,$A12,Matches!$K:$K,"Draw",Matches!$A:$A,"<>Friendly")+COUNTIFS(Matches!$H:$H,$A12,Matches!$K:$K,"Draw",Matches!$A:$A,"<>Friendly")) | G12: =D12-E12-F12 | H12: =IF($A12="",0,SUMIFS(Matches!$E:$E,Matches!$C:$C,$A12,Matches!$I:$I,"Final",Matches!$A:$A,"<>Friendly")+SUMIFS(Matches!$F:$F,Matches!$H:$H,$A12,Matches!$I:$I,"Final",Matches!$A:$A,"<>Friendly")) | I12: =IF($A12="",0,SUMIFS(Matches!$F:$F,Matches!$C:$C,$A12,Matches!$I:$I,"Final",Matches!$A:$A,"<>Friendly")+SUMIFS(Matches!$E:$E,Matches!$H:$H,$A12,Matches!$I:$I,"Final",Matches!$A:$A,"<>Friendly")) | J12: =H12-I12 | K12: =3*E12+F12 | L12: =IF(AND($A12<>"",OR($C12="Yes",D12>0)),K12*1000000+(MAX(-499,MIN(499,J12))+500)*1000+MIN(H12,99)*10+(50-ROW())/10,-1) | M12: =IF($B12="",0,COUNTIFS(Matches!$C:$C,$A12,Matches!$I:$I,"Final",Matches!$A:$A,"Group",Matches!$L:$L,$B12)+COUNTIFS(Matches!$H:$H,$A12,Matches!$I:$I,"Final",Matches!$A:$A,"Group",Matches!$L:$L,$B12)) | N12: =IF($B12="",0,COUNTIFS(Matches!$K:$K,$A12,Matches!$A:$A,"Group",Matches!$L:$L,$B12)) | O12: =IF($B12="",0,COUNTIFS(Matches!$C:$C,$A12,Matches!$K:$K,"Draw",Matches!$A:$A,"Group",Matches!$L:$L,$B12)+COUNTIFS(Matches!$H:$H,$A12,Matches!$K:$K,"Draw",Matches!$A:$A,"Group",Matches!$L:$L,$B12)) | P12: =M12-N12-O12 | Q12: =IF($B12="",0,SUMIFS(Matches!$E:$E,Matches!$C:$C,$A12,Matches!$I:$I,"Final",Matches!$A:$A,"Group",Matches!$L:$L,$B12)+SUMIFS(Matches!$F:$F,Matches!$H:$H,$A12,Matches!$I:$I,"Final",Matches!$A:$A,"Group",Matches!$L:$L,$B12)) | R12: =IF($B12="",0,SUMIFS(Matches!$F:$F,Matches!$C:$C,$A12,Matches!$I:$I,"Final",Matches!$A:$A,"Group",Matches!$L:$L,$B12)+SUMIFS(Matches!$E:$E,Matches!$H:$H,$A12,Matches!$I:$I,"Final",Matches!$A:$A,"Group",Matches!$L:$L,$B12)) | S12: =Q12-R12 | T12: =3*N12+O12 | U12: =IF($B12="",0,IFERROR(MATCH($B12,Settings!$A$15:$A$22,0),0)) | V12: =IF(OR($A12="",U12=0),-1,U12*1000000000+T12*1000000+(MAX(-499,MIN(499,S12))+500)*1000+MIN(Q12,99)*10+(50-ROW())/10) | W12: =IF($A12="",0,COUNTIF('Buy-ins'!$B:$B,$A12)) | X12: =IF($A12="",0,SUMIF('Buy-ins'!$B:$B,$A12,'Buy-ins'!$C:$C)+Settings!$B$3*COUNTIFS('Buy-ins'!$B:$B,$A12,'Buy-ins'!$C:$C,"")) | Y12: =IF($A12="","",'Cash-out'!G12) | Z12: =IF(OR($A12="",Y12=""),"",Y12-X12) | AA12: =IF(X12=0,-1,(IF(Z12="",0,Z12)+100000)*1000000+ROUND(X12*10,0)*10+(50-ROW())/10)
